input.csv
time,sym,side,price,size
09:00:02.834,GOOG,B,779.75,500
09:00:05.003,GOOG,B,779.85,100
09:00:05.520,APPL,S,120.3,300
09:00:05.828,HSBC,S,80.2,700
09:00:09.941,FDP,S,5.15,500
09:00:10.662,HSBC,S,80.4,600
09:00:10.784,APPL,B,119.55,500
09:00:11.095,REYA,B,44.7,100
09:00:14.478,HSBC,S,80.45,100
09:00:15.509,HSBC,S,80.3,700
09:00:16.419,REYA,B,44.65,1000
09:00:23.410,FDP,B,4.75,500
09:00:23.951,REYA,S,45.2,300
09:00:25.109,APPL,S,120.2,700
09:00:25.207,HSBC,S,80.3,700
09:00:25.722,HSBC,B,79.65,900
09:00:26.545,HSBC,B,79.95,900
09:00:28.264,GOOG,B,779.95,500
09:00:30.025,FDP,B,4.75,100
09:00:30.569,FDP,B,4.75,500
09:00:32.657,REYA,S,45.25,400
09:00:38.990,APPL,S,120.4,100
09:00:39.161,GOOG,S,780.2,500
09:00:40.062,APPL,S,120.1,1000
09:00:45.960,REYA,S,45.5,100
09:00:47.420,HSBC,S,80.3,600
09:00:47.446,FDP,S,5.4,100
09:00:53.699,APPL,B,119.55,400
09:00:58.489,FDP,S,5.05,200
09:01:01.026,GOOG,S,780.25,400
09:01:03.213,HSBC,S,80.35,600
09:01:05.798,FDP,B,4.8,400
09:01:08.941,REYA,S,45.35,400
09:01:09.513,FDP,B,4.7,200
09:01:13.383,GOOG,B,779.6,600
09:01:14.470,GOOG,S,780.15,700
09:01:15.690,GOOG,S,780.4,100
09:01:18.818,HSBC,S,80.2,100
09:01:19.345,HSBC,S,80.45,200
09:01:20.878,FDP,B,4.55,300
09:01:21.386,APPL,S,120.4,400
09:01:22.711,HSBC,S,80.4,100
09:01:23.899,REYA,B,44.9,300
09:01:29.533,GOOG,S,780.4,1000
09:01:29.834,FDP,B,4.65,600
09:01:32.056,FDP,S,5.5,100
09:01:35.128,APPL,B,119.65,200
09:01:35.293,FDP,B,4.7,1000
09:01:38.275,FDP,B,4.8,1000
09:01:38.885,HSBC,B,79.75,800
09:01:42.345,HSBC,B,79.8,100
09:01:44.117,HSBC,B,79.9,500
09:01:48.367,FDP,S,5.1,600
09:01:51.566,REYA,S,45.4,800
09:01:52.805,HSBC,B,79.55,300
09:01:53.980,FDP,B,4.6,200
09:01:58.549,HSBC,B,79.75,400
09:02:01.955,HSBC,B,79.85,300
09:02:05.525,APPL,S,120.1,600
09:02:05.758,REYA,B,44.5,1000
09:02:10.979,HSBC,S,80.15,300
09:02:13.881,GOOG,S,780.45,400
09:02:17.354,FDP,S,5.5,800
09:02:20.310,GOOG,B,779.95,600
09:02:21.544,REYA,B,44.5,200
09:02:23.904,REYA,S,45.2,700
09:02:27.597,GOOG,S,780.1,500
09:02:28.276,GOOG,B,779.6,1000
09:02:29.820,REYA,B,44.85,800
09:02:29.823,REYA,B,44.85,700
09:02:31.518,HSBC,B,79.6,1000
09:02:32.551,GOOG,S,780.45,400
09:02:43.115,APPL,B,119.6,300
09:02:46.884,HSBC,B,79.9,400
09:02:52.441,HSBC,S,80.05,900
09:02:52.651,HSBC,S,80.1,200
09:02:53.643,GOOG,B,779.5,1000
09:02:53.830,REYA,S,45.05,500
09:02:58.372,GOOG,S,780.15,200
09:02:59.128,APPL,S,120.35,500
09:03:13.653,GOOG,B,779.65,300
09:03:21.734,FDP,B,4.85,1000
09:03:23.886,GOOG,B,779.5,900
09:03:28.548,GOOG,B,779.95,800
09:03:31.034,HSBC,B,79.6,300
09:03:31.714,APPL,S,120.45,700
09:03:32.342,APPL,S,120.35,1000
09:03:34.227,HSBC,B,79.75,300
09:03:36.505,REYA,S,45.5,400
09:03:39.634,HSBC,B,79.55,700
09:03:40.782,APPL,B,119.55,200
09:03:40.965,FDP,S,5.35,100
09:03:40.995,FDP,B,4.85,400
09:03:41.259,GOOG,B,779.7,600
09:03:42.300,REYA,S,45.4,700
09:03:42.661,HSBC,B,79.75,400
09:03:43.790,GOOG,B,779.55,200
09:03:44.644,FDP,S,5.4,300
09:03:48.271,GOOG,B,779.5,500
09:03:52.345,REYA,B,44.6,1000
09:03:56.020,APPL,B,119.8,500
09:03:57.406,GOOG,S,780.5,800
09:03:59.737,GOOG,B,779.65,700
09:04:03.073,FDP,B,4.85,500
09:04:04.561,HSBC,B,79.95,900
09:04:06.626,GOOG,S,780.1,1000
09:04:17.194,APPL,B,119.95,800
09:04:19.153,HSBC,S,80.05,400
09:04:22.436,GOOG,B,779.75,900
09:04:32.940,HSBC,B,79.95,900
09:04:36.305,REYA,B,44.9,300
09:04:41.150,GOOG,B,779.9,300
09:04:45.847,HSBC,B,79.95,400
09:04:46.467,APPL,S,120.25,600
09:04:50.306,REYA,B,44.6,400
09:04:54.063,REYA,S,45.25,100
09:04:55.884,GOOG,B,779.8,1000
09:04:56.796,REYA,S,45.5,100
09:04:57.390,GOOG,S,780.4,800
09:04:58.178,HSBC,B,79.6,200
09:05:04.800,GOOG,B,779.75,100
09:05:09.558,GOOG,B,779.55,600
09:05:11.202,GOOG,B,779.6,700
09:05:12.329,HSBC,B,79.55,800
09:05:15.703,GOOG,S,780.05,200
09:05:16.350,FDP,S,5.05,600
09:05:17.618,HSBC,B,79.7,500
09:05:21.081,APPL,B,119.8,900
09:05:28.122,GOOG,B,779.75,600
09:05:28.341,APPL,B,119.6,300
09:05:32.176,REYA,B,44.9,900
09:05:32.552,HSBC,B,79.8,900
09:05:38.911,HSBC,B,79.85,800
09:05:39.830,GOOG,S,780.45,1000
09:05:42.194,APPL,B,119.85,200
09:05:47.743,APPL,B,119.75,400
09:05:49.413,GOOG,S,780.1,900
09:05:50.564,APPL,S,120.4,1000
09:05:56.333,GOOG,B,779.85,500
09:05:56.726,HSBC,S,80.4,600
09:05:57.988,FDP,S,5.4,100
09:05:58.118,APPL,B,119.65,700
09:06:02.036,GOOG,B,779.9,700
09:06:02.936,FDP,B,4.65,500
09:06:03.214,FDP,B,4.8,800
09:06:04.091,HSBC,S,80.2,700
09:06:06.844,FDP,S,5.45,800
09:06:07.282,FDP,B,4.5,1000
09:06:09.481,REYA,B,44.9,800
09:06:11.398,REYA,B,44.75,200
09:06:15.327,HSBC,S,80.25,500
09:06:19.594,GOOG,B,779.9,800
09:06:21.140,GOOG,B,779.85,1000
09:06:21.936,GOOG,B,779.7,900
09:06:21.987,APPL,S,120.25,900
09:06:24.441,APPL,S,120.5,200
09:06:24.501,REYA,B,44.8,300
09:06:26.287,GOOG,B,779.9,900
09:06:27.276,GOOG,B,779.55,200
09:06:29.368,APPL,B,119.8,100
09:06:31.737,FDP,B,4.75,300
09:06:34.627,HSBC,B,79.85,600
09:06:38.979,GOOG,S,780.35,400
09:06:39.592,FDP,B,4.65,700
09:06:43.301,GOOG,S,780.45,700
09:06:43.612,FDP,S,5.2,600
09:06:45.134,REYA,B,44.85,600
09:06:48.964,APPL,S,120.4,800
09:06:49.911,REYA,S,45.35,200
09:06:51.822,REYA,B,44.95,900
09:06:51.838,GOOG,S,780.35,900
09:06:52.116,APPL,S,120.4,200
09:06:52.966,HSBC,B,79.7,700
09:06:54.522,GOOG,S,780.1,800
09:06:57.415,FDP,S,5.35,500
09:06:57.512,GOOG,B,779.65,300
09:06:57.996,APPL,B,119.9,1000
09:06:59.450,APPL,S,120.05,100
09:07:00.924,FDP,S,5.45,400
09:07:01.430,REYA,B,44.6,900
09:07:03.338,FDP,S,5.45,400
09:07:04.277,APPL,S,120.3,500
09:07:04.474,REYA,S,45.15,200
09:07:15.343,APPL,S,120.2,700
09:07:15.958,REYA,B,44.65,100
09:07:17.541,FDP,S,5.45,600
09:07:21.461,HSBC,S,80.4,1000
09:07:24.030,REYA,S,45.05,1000
09:07:24.213,HSBC,B,79.55,900
09:07:25.371,APPL,S,120.4,200
09:07:33.842,APPL,S,120.4,100
09:07:36.778,FDP,S,5.45,900
09:07:38.350,GOOG,S,780.05,900
09:07:38.889,GOOG,S,780.3,600
09:07:48.963,FDP,S,5.4,600
09:07:49.478,FDP,S,5.3,1000
09:07:50.837,APPL,B,119.5,900
09:07:58.854,APPL,B,119.5,900
09:08:05.380,GOOG,S,780.05,400
09:08:06.424,APPL,B,119.85,100
09:08:09.120,GOOG,S,780.3,200
09:08:11.606,HSBC,B,79.6,600
09:08:12.219,FDP,B,4.65,900
09:08:13.369,REYA,B,44.85,700
09:08:13.582,FDP,B,4.8,1000
09:08:20.749,FDP,S,5.1,600
09:08:21.490,APPL,S,120.2,700
09:08:23.894,FDP,S,5.1,400
09:08:24.102,HSBC,B,79.9,600
09:08:27.248,APPL,B,119.75,400
09:08:33.477,APPL,B,119.65,600
09:08:34.986,GOOG,B,779.95,100
09:08:36.434,HSBC,S,80.35,600
09:08:48.610,GOOG,S,780.2,800
09:08:53.450,HSBC,S,80.15,100
09:08:54.264,GOOG,B,779.95,200
09:08:57.290,APPL,B,119.75,200
09:08:59.247,HSBC,S,80.4,1000
09:09:00.348,FDP,S,5.25,300
09:09:04.031,HSBC,S,80.35,700
09:09:04.972,FDP,S,5.5,200
09:09:07.238,APPL,S,120.15,800
09:09:10.638,APPL,B,119.85,100
09:09:11.569,FDP,B,4.95,400
09:09:15.444,FDP,B,4.8,900
09:09:18.026,REYA,S,45.45,200
09:09:18.861,REYA,S,45.4,200
09:09:20.396,HSBC,B,79.6,700
09:09:25.584,APPL,B,119.95,400
09:09:27.532,GOOG,S,780.2,300
09:09:30.257,REYA,S,45.2,900
09:09:39.479,APPL,S,120.5,100
09:09:39.900,GOOG,B,779.65,1000
09:09:42.532,HSBC,B,79.75,800
09:09:43.426,APPL,B,119.85,1000
09:09:44.415,APPL,B,119.7,800
09:09:46.474,GOOG,S,780.15,300
09:09:46.844,REYA,B,44.6,1000
09:09:49.708,APPL,S,120.15,400
09:09:51.691,FDP,B,4.75,200
09:09:52.068,FDP,S,5.4,600
09:09:54.213,FDP,S,5.4,800
09:09:55.725,GOOG,S,780.5,500
09:09:59.300,APPL,B,119.75,700
09:10:01.847,GOOG,S,780.4,200
09:10:02.462,APPL,B,119.95,100
09:10:03.118,APPL,S,120.15,400
09:10:09.676,APPL,S,120.1,300
09:10:18.969,APPL,B,119.9,800
09:10:22.208,REYA,S,45.25,1000
09:10:23.396,GOOG,S,780.05,1000
09:10:25.010,GOOG,B,779.75,100
09:10:27.038,APPL,B,119.65,1000
09:10:29.694,HSBC,S,80.15,300
09:10:29.820,HSBC,B,79.7,1000
09:10:35.402,HSBC,B,79.95,700
09:10:35.930,HSBC,S,80.15,400
09:10:36.457,HSBC,B,79.65,300
09:10:37.804,HSBC,S,80.1,400
09:10:38.939,GOOG,S,780.2,700
09:10:41.278,REYA,S,45.35,300
09:10:49.825,GOOG,S,780.1,100
09:10:53.195,GOOG,B,779.7,300
09:10:53.404,GOOG,B,779.6,1000
09:10:57.433,FDP,S,5.5,400
09:11:01.083,HSBC,S,80.35,300
09:11:01.814,FDP,S,5.3,900
09:11:02.578,APPL,B,119.9,100
09:11:03.335,HSBC,S,80.35,600
